Workbook
Name Abierto: OFFSET(Reportes!$BA$12,1,0,COUNTA(Reportes!$AZ$13:$AZ$116)-COUNTIF(Reportes!$AZ$13:$AZ$116,"")+1,1)
Name Nombre: OFFSET(Reportes!$AZ$12,1,0,COUNTA(Reportes!$AZ$13:$AZ$116)-COUNTIF(Reportes!$AZ$13:$AZ$116,"")+1,1)
Name Resuelto: OFFSET(Reportes!$BB$12,1,0,COUNTA(Reportes!$AZ$13:$AZ$116)-COUNTIF(Reportes!$AZ$13:$AZ$116,"")+1,1)
Name SegmentaciónDeDatos_Asignado_a: #N/A
Name SegmentaciónDeDatos_Asignado_a1: #N/A
Name SegmentaciónDeDatos_Dependencia: #N/A
Name SegmentaciónDeDatos_Estado: #N/A

Sheet Programación
A5: Programación:
A6: # Tickets abiertos | M6: Resumen
A7: Urgente | D7: Alta | G7: Media | J7: Baja | M7: Agrupa | P7: Baja
A8: # | B8: Dias ab. | C8: Jer. Inv | D8: # | E8: Dias ab. | F8: Jer. Inv | G8: # | H8: Dias ab. | I8: Jer. Inv | J8: # | K8: Dias ab. | L8: Jer. Inv | M8: Jer. Inv | N8: Dias ab. | O8: # | P8: Contador | Q8: # ord. | R8: Dias ab. Ordenado | T8: Tickets | U8: Cantidad | W8: N° | X8: Nombre | Y8: Nombre ordenado
A9: =IF(AND(Registro!D8="Abierto",Registro!E8="Urgente"),Registro!B8,"") | B9: =IF(AND(Registro!D8="Abierto",Registro!E8="Urgente"),TODAY()-Registro!R8,"") | C9: =IF(AND(Registro!D8="Abierto",Registro!E8="Urgente"),RANK(B9,$B$9:$B$1000,0)+COUNTIF($B$9:B9,B9)-1,"") | D9: =IF(AND(Registro!D8="Abierto",Registro!E8="Alta"),Registro!B8,"") | E9: =IF(AND(Registro!D8="Abierto",Registro!E8="Alta"),TODAY()-Registro!R8,"") | F9: =IF(AND(Registro!D8="Abierto",Registro!E8="Alta"),RANK(E9,$E$9:$E$1000,0)+COUNTIF($E$9:E9,E9)-1+MAX(C$5:C$1000),"") | G9: =IF(AND(Registro!D8="Abierto",Registro!E8="Media"),Registro!B8,"") | H9: =IF(AND(Registro!D8="Abierto",Registro!E8="Media"),TODAY()-Registro!R8,"") | I9: =IF(AND(Registro!D8="Abierto",Registro!E8="Media"),RANK(H9,$H$9:$H$1000,0)+COUNTIF($H$9:H9,H9)-1+MAX(C$5:C$1000,F$5:F$1000),"") | J9: =IF(AND(Registro!D8="Abierto",Registro!E8="Baja"),Registro!B8,"") | K9: =IF(AND(Registro!D8="Abierto",Registro!E8="Baja"),TODAY()-Registro!R8,"") | L9: =IF(AND(Registro!D8="Abierto",Registro!E8="Baja"),RANK(K9,$K$9:$K$1000,0)+COUNTIF($K$9:K9,K9)-1+MAX(C$5:C$1000,F$5:F$1000,I$5:I$1000),"") | M9: =IF(OR(Registro!D8="Resuelto",Registro!D8=""),"",SUM(C9,F9,I9,L9)) | N9: =IF(OR(Registro!D8="Resuelto",Registro!D8=""),"",SUM(B9,E9,H9,K9)) | O9: =IF(OR(Registro!D8="Resuelto",Registro!D8=""),"",_xlfn.CONCAT(A9,D9,G9,J9)) | P9: 1 | Q9: =IF(ISNA(VLOOKUP(P9,$M$9:$O$1000,3,FALSE))=TRUE,"",VLOOKUP(P9,$M$9:$O$1000,3,FALSE)) -> 6405-PFIN-26 | R9: =IF(ISNA(VLOOKUP(P9,$M$9:$O$1000,2,FALSE))=TRUE,"",VLOOKUP(P9,$M$9:$O$1000,2,FALSE)) -> 3 | T9: Abierto | U9: =COUNTIF(Registro!D:D,T9) -> 44 | W9: =IF(X9="","",MAX($W$5:W8)+1) -> 1 | X9: =IF(Registro!M8="","",Registro!M8) -> Gestor 1 | Y9: =IF(ISNA(VLOOKUP(P9,$W$9:$X$1000,2,FALSE))=TRUE,"",VLOOKUP(P9,$W$9:$X$1000,2,FALSE)) -> Gestor 1
A10: =IF(AND(Registro!D9="Abierto",Registro!E9="Urgente"),Registro!B9,"") | B10: =IF(AND(Registro!D9="Abierto",Registro!E9="Urgente"),TODAY()-Registro!R9,"") | C10: =IF(AND(Registro!D9="Abierto",Registro!E9="Urgente"),RANK(B10,$B$9:$B$1000,0)+COUNTIF($B$9:B10,B10)-1,"") | D10: =IF(AND(Registro!D9="Abierto",Registro!E9="Alta"),Registro!B9,"") | E10: =IF(AND(Registro!D9="Abierto",Registro!E9="Alta"),TODAY()-Registro!R9,"") | F10: =IF(AND(Registro!D9="Abierto",Registro!E9="Alta"),RANK(E10,$E$9:$E$1000,0)+COUNTIF($E$9:E10,E10)-1+MAX(C$5:C$1000),"") | G10: =IF(AND(Registro!D9="Abierto",Registro!E9="Media"),Registro!B9,"") | H10: =IF(AND(Registro!D9="Abierto",Registro!E9="Media"),TODAY()-Registro!R9,"") | I10: =IF(AND(Registro!D9="Abierto",Registro!E9="Media"),RANK(H10,$H$9:$H$1000,0)+COUNTIF($H$9:H10,H10)-1+MAX(C$5:C$1000,F$5:F$1000),"") | J10: =IF(AND(Registro!D9="Abierto",Registro!E9="Baja"),Registro!B9,"") | K10: =IF(AND(Registro!D9="Abierto",Registro!E9="Baja"),TODAY()-Registro!R9,"") | L10: =IF(AND(Registro!D9="Abierto",Registro!E9="Baja"),RANK(K10,$K$9:$K$1000,0)+COUNTIF($K$9:K10,K10)-1+MAX(C$5:C$1000,F$5:F$1000,I$5:I$1000),"") | M10: =IF(OR(Registro!D9="Resuelto",Registro!D9=""),"",SUM(C10,F10,I10,L10)) | N10: =IF(OR(Registro!D9="Resuelto",Registro!D9=""),"",SUM(B10,E10,H10,K10)) | O10: =IF(OR(Registro!D9="Resuelto",Registro!D9=""),"",_xlfn.CONCAT(A10,D10,G10,J10)) | P10: 2 | Q10: =IF(ISNA(VLOOKUP(P10,$M$9:$O$1000,3,FALSE))=TRUE,"",VLOOKUP(P10,$M$9:$O$1000,3,FALSE)) -> 6411-PFIN-26 | R10: =IF(ISNA(VLOOKUP(P10,$M$9:$O$1000,2,FALSE))=TRUE,"",VLOOKUP(P10,$M$9:$O$1000,2,FALSE)) -> -14 | T10: Urgente | U10: =COUNTIFS(Registro!$D:$D,$T$9,Registro!$E:$E,T10) -> 2 | W10: =IF(X10="","",MAX($W$5:W9)+1) -> 2 | X10: =IF(Registro!M9="","",IF(COUNTIF($X$8:X9,Registro!M9)=0,Registro!M9,"")) -> Gestor 4 | Y10: =IF(ISNA(VLOOKUP(P10,$W$9:$X$1000,2,FALSE))=TRUE,"",VLOOKUP(P10,$W$9:$X$1000,2,FALSE)) -> Gestor 4
A11: =IF(AND(Registro!D10="Abierto",Registro!E10="Urgente"),Registro!B10,"") | B11: =IF(AND(Registro!D10="Abierto",Registro!E10="Urgente"),TODAY()-Registro!R10,"") | C11: =IF(AND(Registro!D10="Abierto",Registro!E10="Urgente"),RANK(B11,$B$9:$B$1000,0)+COUNTIF($B$9:B11,B11)-1,"") | D11: =IF(AND(Registro!D10="Abierto",Registro!E10="Alta"),Registro!B10,"") | E11: =IF(AND(Registro!D10="Abierto",Registro!E10="Alta"),TODAY()-Registro!R10,"") | F11: =IF(AND(Registro!D10="Abierto",Registro!E10="Alta"),RANK(E11,$E$9:$E$1000,0)+COUNTIF($E$9:E11,E11)-1+MAX(C$5:C$1000),"") | G11: =IF(AND(Registro!D10="Abierto",Registro!E10="Media"),Registro!B10,"") | H11: =IF(AND(Registro!D10="Abierto",Registro!E10="Media"),TODAY()-Registro!R10,"") | I11: =IF(AND(Registro!D10="Abierto",Registro!E10="Media"),RANK(H11,$H$9:$H$1000,0)+COUNTIF($H$9:H11,H11)-1+MAX(C$5:C$1000,F$5:F$1000),"") | J11: =IF(AND(Registro!D10="Abierto",Registro!E10="Baja"),Registro!B10,"") | K11: =IF(AND(Registro!D10="Abierto",Registro!E10="Baja"),TODAY()-Registro!R10,"") | L11: =IF(AND(Registro!D10="Abierto",Registro!E10="Baja"),RANK(K11,$K$9:$K$1000,0)+COUNTIF($K$9:K11,K11)-1+MAX(C$5:C$1000,F$5:F$1000,I$5:I$1000),"") | M11: =IF(OR(Registro!D10="Resuelto",Registro!D10=""),"",SUM(C11,F11,I11,L11)) | N11: =IF(OR(Registro!D10="Resuelto",Registro!D10=""),"",SUM(B11,E11,H11,K11)) | O11: =IF(OR(Registro!D10="Resuelto",Registro!D10=""),"",_xlfn.CONCAT(A11,D11,G11,J11)) | P11: 3 | Q11: =IF(ISNA(VLOOKUP(P11,$M$9:$O$1000,3,FALSE))=TRUE,"",VLOOKUP(P11,$M$9:$O$1000,3,FALSE)) -> 6404-PFIN-26 | R11: =IF(ISNA(VLOOKUP(P11,$M$9:$O$1000,2,FALSE))=TRUE,"",VLOOKUP(P11,$M$9:$O$1000,2,FALSE)) -> 46310 | T11: Alta | U11: =COUNTIFS(Registro!$D:$D,$T$9,Registro!$E:$E,T11) -> 8 | W11: =IF(X11="","",MAX($W$5:W10)+1) -> 3 | X11: =IF(Registro!M10="","",IF(COUNTIF($X$8:X10,Registro!M10)=0,Registro!M10,"")) -> Gestor 5 | Y11: =IF(ISNA(VLOOKUP(P11,$W$9:$X$1000,2,FALSE))=TRUE,"",VLOOKUP(P11,$W$9:$X$1000,2,FALSE)) -> Gestor 5
A12: =IF(AND(Registro!D11="Abierto",Registro!E11="Urgente"),Registro!B11,"") | B12: =IF(AND(Registro!D11="Abierto",Registro!E11="Urgente"),TODAY()-Registro!R11,"") | C12: =IF(AND(Registro!D11="Abierto",Registro!E11="Urgente"),RANK(B12,$B$9:$B$1000,0)+COUNTIF($B$9:B12,B12)-1,"") | D12: =IF(AND(Registro!D11="Abierto",Registro!E11="Alta"),Registro!B11,"") | E12: =IF(AND(Registro!D11="Abierto",Registro!E11="Alta"),TODAY()-Registro!R11,"") | F12: =IF(AND(Registro!D11="Abierto",Registro!E11="Alta"),RANK(E12,$E$9:$E$1000,0)+COUNTIF($E$9:E12,E12)-1+MAX(C$5:C$1000),"") | G12: =IF(AND(Registro!D11="Abierto",Registro!E11="Media"),Registro!B11,"") | H12: =IF(AND(Registro!D11="Abierto",Registro!E11="Media"),TODAY()-Registro!R11,"") | I12: =IF(AND(Registro!D11="Abierto",Registro!E11="Media"),RANK(H12,$H$9:$H$1000,0)+COUNTIF($H$9:H12,H12)-1+MAX(C$5:C$1000,F$5:F$1000),"") | J12: =IF(AND(Registro!D11="Abierto",Registro!E11="Baja"),Registro!B11,"") | K12: =IF(AND(Registro!D11="Abierto",Registro!E11="Baja"),TODAY()-Registro!R11,"") | L12: =IF(AND(Registro!D11="Abierto",Registro!E11="Baja"),RANK(K12,$K$9:$K$1000,0)+COUNTIF($K$9:K12,K12)-1+MAX(C$5:C$1000,F$5:F$1000,I$5:I$1000),"") | M12: =IF(OR(Registro!D11="Resuelto",Registro!D11=""),"",SUM(C12,F12,I12,L12)) | N12: =IF(OR(Registro!D11="Resuelto",Registro!D11=""),"",SUM(B12,E12,H12,K12)) | O12: =IF(OR(Registro!D11="Resuelto",Registro!D11=""),"",_xlfn.CONCAT(A12,D12,G12,J12)) | P12: 4 | Q12: =IF(ISNA(VLOOKUP(P12,$M$9:$O$1000,3,FALSE))=TRUE,"",VLOOKUP(P12,$M$9:$O$1000,3,FALSE)) -> 6371-PFIN-26 | R12: =IF(ISNA(VLOOKUP(P12,$M$9:$O$1000,2,FALSE))=TRUE,"",VLOOKUP(P12,$M$9:$O$1000,2,FALSE)) -> 8 | T12: Media | U12: =COUNTIFS(Registro!$D:$D,$T$9,Registro!$E:$E,T12) -> 8 | W12: =IF(X12="","",MAX($W$5:W11)+1) -> 4 | X12: =IF(Registro!M11="","",IF(COUNTIF($X$8:X11,Registro!M11)=0,Registro!M11,"")) -> Gestor 3 | Y12: =IF(ISNA(VLOOKUP(P12,$W$9:$X$1000,2,FALSE))=TRUE,"",VLOOKUP(P12,$W$9:$X$1000,2,FALSE)) -> Gestor 3
A13: =IF(AND(Registro!D12="Abierto",Registro!E12="Urgente"),Registro!B12,"") | B13: =IF(AND(Registro!D12="Abierto",Registro!E12="Urgente"),TODAY()-Registro!R12,"") | C13: =IF(AND(Registro!D12="Abierto",Registro!E12="Urgente"),RANK(B13,$B$9:$B$1000,0)+COUNTIF($B$9:B13,B13)-1,"") | D13: =IF(AND(Registro!D12="Abierto",Registro!E12="Alta"),Registro!B12,"") | E13: =IF(AND(Registro!D12="Abierto",Registro!E12="Alta"),TODAY()-Registro!R12,"") | F13: =IF(AND(Registro!D12="Abierto",Registro!E12="Alta"),RANK(E13,$E$9:$E$1000,0)+COUNTIF($E$9:E13,E13)-1+MAX(C$5:C$1000),"") | G13: =IF(AND(Registro!D12="Abierto",Registro!E12="Media"),Registro!B12,"") | H13: =IF(AND(Registro!D12="Abierto",Registro!E12="Media"),TODAY()-Registro!R12,"") | I13: =IF(AND(Registro!D12="Abierto",Registro!E12="Media"),RANK(H13,$H$9:$H$1000,0)+COUNTIF($H$9:H13,H13)-1+MAX(C$5:C$1000,F$5:F$1000),"") | J13: =IF(AND(Registro!D12="Abierto",Registro!E12="Baja"),Registro!B12,"") | K13: =IF(AND(Registro!D12="Abierto",Registro!E12="Baja"),TODAY()-Registro!R12,"") | L13: =IF(AND(Registro!D12="Abierto",Registro!E12="Baja"),RANK(K13,$K$9:$K$1000,0)+COUNTIF($K$9:K13,K13)-1+MAX(C$5:C$1000,F$5:F$1000,I$5:I$1000),"") | M13: =IF(OR(Registro!D12="Resuelto",Registro!D12=""),"",SUM(C13,F13,I13,L13)) | N13: =IF(OR(Registro!D12="Resuelto",Registro!D12=""),"",SUM(B13,E13,H13,K13)) | O13: =IF(OR(Registro!D12="Resuelto",Registro!D12=""),"",_xlfn.CONCAT(A13,D13,G13,J13)) | P13: 5 | Q13: =IF(ISNA(VLOOKUP(P13,$M$9:$O$1000,3,FALSE))=TRUE,"",VLOOKUP(P13,$M$9:$O$1000,3,FALSE)) -> 6375-PFIN-26 | R13: =IF(ISNA(VLOOKUP(P13,$M$9:$O$1000,2,FALSE))=TRUE,"",VLOOKUP(P13,$M$9:$O$1000,2,FALSE)) -> 8 | T13: Baja | U13: =COUNTIFS(Registro!$D:$D,$T$9,Registro!$E:$E,T13) -> 26 | W13: =IF(X13="","",MAX($W$5:W12)+1) | X13: =IF(Registro!M12="","",IF(COUNTIF($X$8:X12,Registro!M12)=0,Registro!M12,"")) | Y13: =IF(ISNA(VLOOKUP(P13,$W$9:$X$1000,2,FALSE))=TRUE,"",VLOOKUP(P13,$W$9:$X$1000,2,FALSE)) -> Gestor 2
A14: =IF(AND(Registro!D13="Abierto",Registro!E13="Urgente"),Registro!B13,"") | B14: =IF(AND(Registro!D13="Abierto",Registro!E13="Urgente"),TODAY()-Registro!R13,"") | C14: =IF(AND(Registro!D13="Abierto",Registro!E13="Urgente"),RANK(B14,$B$9:$B$1000,0)+COUNTIF($B$9:B14,B14)-1,"") | D14: =IF(AND(Registro!D13="Abierto",Registro!E13="Alta"),Registro!B13,"") | E14: =IF(AND(Registro!D13="Abierto",Registro!E13="Alta"),TODAY()-Registro!R13,"") | F14: =IF(AND(Registro!D13="Abierto",Registro!E13="Alta"),RANK(E14,$E$9:$E$1000,0)+COUNTIF($E$9:E14,E14)-1+MAX(C$5:C$1000),"") | G14: =IF(AND(Registro!D13="Abierto",Registro!E13="Media"),Registro!B13,"") | H14: =IF(AND(Registro!D13="Abierto",Registro!E13="Media"),TODAY()-Registro!R13,"") | I14: =IF(AND(Registro!D13="Abierto",Registro!E13="Media"),RANK(H14,$H$9:$H$1000,0)+COUNTIF($H$9:H14,H14)-1+MAX(C$5:C$1000,F$5:F$1000),"") | J14: =IF(AND(Registro!D13="Abierto",Registro!E13="Baja"),Registro!B13,"") -> 6281-PFIN-26 | K14: =IF(AND(Registro!D13="Abierto",Registro!E13="Baja"),TODAY()-Registro!R13,"") -> 2 | L14: =IF(AND(Registro!D13="Abierto",Registro!E13="Baja"),RANK(K14,$K$9:$K$1000,0)+COUNTIF($K$9:K14,K14)-1+MAX(C$5:C$1000,F$5:F$1000,I$5:I$1000),"") -> 27 | M14: =IF(OR(Registro!D13="Resuelto",Registro!D13=""),"",SUM(C14,F14,I14,L14)) -> 27 | N14: =IF(OR(Registro!D13="Resuelto",Registro!D13=""),"",SUM(B14,E14,H14,K14)) -> 2 | O14: =IF(OR(Registro!D13="Resuelto",Registro!D13=""),"",_xlfn.CONCAT(A14,D14,G14,J14)) -> 6281-PFIN-26 | P14: 6 | Q14: =IF(ISNA(VLOOKUP(P14,$M$9:$O$1000,3,FALSE))=TRUE,"",VLOOKUP(P14,$M$9:$O$1000,3,FALSE)) -> 6377-PFIN-26 | R14: =IF(ISNA(VLOOKUP(P14,$M$9:$O$1000,2,FALSE))=TRUE,"",VLOOKUP(P14,$M$9:$O$1000,2,FALSE)) -> 7 | W14: =IF(X14="","",MAX($W$5:W13)+1) | X14: =IF(Registro!M13="","",IF(COUNTIF($X$8:X13,Registro!M13)=0,Registro!M13,"")) | Y14: =IF(ISNA(VLOOKUP(P14,$W$9:$X$1000,2,FALSE))=TRUE,"",VLOOKUP(P14,$W$9:$X$1000,2,FALSE))
A15: =IF(AND(Registro!D14="Abierto",Registro!E14="Urgente"),Registro!B14,"") | B15: =IF(AND(Registro!D14="Abierto",Registro!E14="Urgente"),TODAY()-Registro!R14,"") | C15: =IF(AND(Registro!D14="Abierto",Registro!E14="Urgente"),RANK(B15,$B$9:$B$1000,0)+COUNTIF($B$9:B15,B15)-1,"") | D15: =IF(AND(Registro!D14="Abierto",Registro!E14="Alta"),Registro!B14,"") | E15: =IF(AND(Registro!D14="Abierto",Registro!E14="Alta"),TODAY()-Registro!R14,"") | F15: =IF(AND(Registro!D14="Abierto",Registro!E14="Alta"),RANK(E15,$E$9:$E$1000,0)+COUNTIF($E$9:E15,E15)-1+MAX(C$5:C$1000),"") | G15: =IF(AND(Registro!D14="Abierto",Registro!E14="Media"),Registro!B14,"") | H15: =IF(AND(Registro!D14="Abierto",Registro!E14="Media"),TODAY()-Registro!R14,"") | I15: =IF(AND(Registro!D14="Abierto",Registro!E14="Media"),RANK(H15,$H$9:$H$1000,0)+COUNTIF($H$9:H15,H15)-1+MAX(C$5:C$1000,F$5:F$1000),"") | J15: =IF(AND(Registro!D14="Abierto",Registro!E14="Baja"),Registro!B14,"") -> 6283-PFIN-26 | K15: =IF(AND(Registro!D14="Abierto",Registro!E14="Baja"),TODAY()-Registro!R14,"") -> 6 | L15: =IF(AND(Registro!D14="Abierto",Registro!E14="Baja"),RANK(K15,$K$9:$K$1000,0)+COUNTIF($K$9:K15,K15)-1+MAX(C$5:C$1000,F$5:F$1000,I$5:I$1000),"") -> 26 | M15: =IF(OR(Registro!D14="Resuelto",Registro!D14=""),"",SUM(C15,F15,I15,L15)) -> 26 | N15: =IF(OR(Registro!D14="Resuelto",Registro!D14=""),"",SUM(B15,E15,H15,K15)) -> 6 | O15: =IF(OR(Registro!D14="Resuelto",Registro!D14=""),"",_xlfn.CONCAT(A15,D15,G15,J15)) -> 6283-PFIN-26 | P15: 7 | Q15: =IF(ISNA(VLOOKUP(P15,$M$9:$O$1000,3,FALSE))=TRUE,"",VLOOKUP(P15,$M$9:$O$1000,3,FALSE)) -> 6373-PFIN-26 | R15: =IF(ISNA(VLOOKUP(P15,$M$9:$O$1000,2,FALSE))=TRUE,"",VLOOKUP(P15,$M$9:$O$1000,2,FALSE)) -> 3 | W15: =IF(X15="","",MAX($W$5:W14)+1) | X15: =IF(Registro!M14="","",IF(COUNTIF($X$8:X14,Registro!M14)=0,Registro!M14,"")) | Y15: =IF(ISNA(VLOOKUP(P15,$W$9:$X$1000,2,FALSE))=TRUE,"",VLOOKUP(P15,$W$9:$X$1000,2,FALSE))
A16: =IF(AND(Registro!D15="Abierto",Registro!E15="Urgente"),Registro!B15,"") | B16: =IF(AND(Registro!D15="Abierto",Registro!E15="Urgente"),TODAY()-Registro!R15,"") | C16: =IF(AND(Registro!D15="Abierto",Registro!E15="Urgente"),RANK(B16,$B$9:$B$1000,0)+COUNTIF($B$9:B16,B16)-1,"") | D16: =IF(AND(Registro!D15="Abierto",Registro!E15="Alta"),Registro!B15,"") | E16: =IF(AND(Registro!D15="Abierto",Registro!E15="Alta"),TODAY()-Registro!R15,"") | F16: =IF(AND(Registro!D15="Abierto",Registro!E15="Alta"),RANK(E16,$E$9:$E$1000,0)+COUNTIF($E$9:E16,E16)-1+MAX(C$5:C$1000),"") | G16: =IF(AND(Registro!D15="Abierto",Registro!E15="Media"),Registro!B15,"") | H16: =IF(AND(Registro!D15="Abierto",Registro!E15="Media"),TODAY()-Registro!R15,"") | I16: =IF(AND(Registro!D15="Abierto",Registro!E15="Media"),RANK(H16,$H$9:$H$1000,0)+COUNTIF($H$9:H16,H16)-1+MAX(C$5:C$1000,F$5:F$1000),"") | J16: =IF(AND(Registro!D15="Abierto",Registro!E15="Baja"),Registro!B15,"") -> 6284-PFIN-26 | K16: =IF(AND(Registro!D15="Abierto",Registro!E15="Baja"),TODAY()-Registro!R15,"") -> -19 | L16: =IF(AND(Registro!D15="Abierto",Registro!E15="Baja"),RANK(K16,$K$9:$K$1000,0)+COUNTIF($K$9:K16,K16)-1+MAX(C$5:C$1000,F$5:F$1000,I$5:I$1000),"") -> 35 | M16: =IF(OR(Registro!D15="Resuelto",Registro!D15=""),"",SUM(C16,F16,I16,L16)) -> 35 | N16: =IF(OR(Registro!D15="Resuelto",Registro!D15=""),"",SUM(B16,E16,H16,K16)) -> -19 | O16: =IF(OR(Registro!D15="Resuelto",Registro!D15=""),"",_xlfn.CONCAT(A16,D16,G16,J16)) -> 6284-PFIN-26 | P16: 8 | Q16: =IF(ISNA(VLOOKUP(P16,$M$9:$O$1000,3,FALSE))=TRUE,"",VLOOKUP(P16,$M$9:$O$1000,3,FALSE)) -> 6412-PFIN-26 | R16: =IF(ISNA(VLOOKUP(P16,$M$9:$O$1000,2,FALSE))=TRUE,"",VLOOKUP(P16,$M$9:$O$1000,2,FALSE)) -> -4 | W16: =IF(X16="","",MAX($W$5:W15)+1) | X16: =IF(Registro!M15="","",IF(COUNTIF($X$8:X15,Registro!M15)=0,Registro!M15,"")) | Y16: =IF(ISNA(VLOOKUP(P16,$W$9:$X$1000,2,FALSE))=TRUE,"",VLOOKUP(P16,$W$9:$X$1000,2,FALSE))
A17: =IF(AND(Registro!D16="Abierto",Registro!E16="Urgente"),Registro!B16,"") | B17: =IF(AND(Registro!D16="Abierto",Registro!E16="Urgente"),TODAY()-Registro!R16,"") | C17: =IF(AND(Registro!D16="Abierto",Registro!E16="Urgente"),RANK(B17,$B$9:$B$1000,0)+COUNTIF($B$9:B17,B17)-1,"") | D17: =IF(AND(Registro!D16="Abierto",Registro!E16="Alta"),Registro!B16,"") | E17: =IF(AND(Registro!D16="Abierto",Registro!E16="Alta"),TODAY()-Registro!R16,"") | F17: =IF(AND(Registro!D16="Abierto",Registro!E16="Alta"),RANK(E17,$E$9:$E$1000,0)+COUNTIF($E$9:E17,E17)-1+MAX(C$5:C$1000),"") | G17: =IF(AND(Registro!D16="Abierto",Registro!E16="Media"),Registro!B16,"") | H17: =IF(AND(Registro!D16="Abierto",Registro!E16="Media"),TODAY()-Registro!R16,"") | I17: =IF(AND(Registro!D16="Abierto",Registro!E16="Media"),RANK(H17,$H$9:$H$1000,0)+COUNTIF($H$9:H17,H17)-1+MAX(C$5:C$1000,F$5:F$1000),"") | J17: =IF(AND(Registro!D16="Abierto",Registro!E16="Baja"),Registro!B16,"") -> 6286-PFIN-26 | K17: =IF(AND(Registro!D16="Abierto",Registro!E16="Baja"),TODAY()-Registro!R16,"") -> -40 | L17: =IF(AND(Registro!D16="Abierto",Registro!E16="Baja"),RANK(K17,$K$9:$K$1000,0)+COUNTIF($K$9:K17,K17)-1+MAX(C$5:C$1000,F$5:F$1000,I$5:I$1000),"") -> 43 | M17: =IF(OR(Registro!D16="Resuelto",Registro!D16=""),"",SUM(C17,F17,I17,L17)) -> 43 | N17: =IF(OR(Registro!D16="Resuelto",Registro!D16=""),"",SUM(B17,E17,H17,K17)) -> -40 | O17: =IF(OR(Registro!D16="Resuelto",Registro!D16=""),"",_xlfn.CONCAT(A17,D17,G17,J17)) -> 6286-PFIN-26 | P17: 9 | Q17: =IF(ISNA(VLOOKUP(P17,$M$9:$O$1000,3,FALSE))=TRUE,"",VLOOKUP(P17,$M$9:$O$1000,3,FALSE)) -> 6378-PFIN-26 | R17: =IF(ISNA(VLOOKUP(P17,$M$9:$O$1000,2,FALSE))=TRUE,"",VLOOKUP(P17,$M$9:$O$1000,2,FALSE)) -> -6 | W17: =IF(X17="","",MAX($W$5:W16)+1) | X17: =IF(Registro!M16="","",IF(COUNTIF($X$8:X16,Registro!M16)=0,Registro!M16,"")) | Y17: =IF(ISNA(VLOOKUP(P17,$W$9:$X$1000,2,FALSE))=TRUE,"",VLOOKUP(P17,$W$9:$X$1000,2,FALSE))
A18: =IF(AND(Registro!D17="Abierto",Registro!E17="Urgente"),Registro!B17,"") | B18: =IF(AND(Registro!D17="Abierto",Registro!E17="Urgente"),TODAY()-Registro!R17,"") | C18: =IF(AND(Registro!D17="Abierto",Registro!E17="Urgente"),RANK(B18,$B$9:$B$1000,0)+COUNTIF($B$9:B18,B18)-1,"") | D18: =IF(AND(Registro!D17="Abierto",Registro!E17="Alta"),Registro!B17,"") | E18: =IF(AND(Registro!D17="Abierto",Registro!E17="Alta"),TODAY()-Registro!R17,"") | F18: =IF(AND(Registro!D17="Abierto",Registro!E17="Alta"),RANK(E18,$E$9:$E$1000,0)+COUNTIF($E$9:E18,E18)-1+MAX(C$5:C$1000),"") | G18: =IF(AND(Registro!D17="Abierto",Registro!E17="Media"),Registro!B17,"") | H18: =IF(AND(Registro!D17="Abierto",Registro!E17="Media"),TODAY()-Registro!R17,"") | I18: =IF(AND(Registro!D17="Abierto",Registro!E17="Media"),RANK(H18,$H$9:$H$1000,0)+COUNTIF($H$9:H18,H18)-1+MAX(C$5:C$1000,F$5:F$1000),"") | J18: =IF(AND(Registro!D17="Abierto",Registro!E17="Baja"),Registro!B17,"") | K18: =IF(AND(Registro!D17="Abierto",Registro!E17="Baja"),TODAY()-Registro!R17,"") | L18: =IF(AND(Registro!D17="Abierto",Registro!E17="Baja"),RANK(K18,$K$9:$K$1000,0)+COUNTIF($K$9:K18,K18)-1+MAX(C$5:C$1000,F$5:F$1000,I$5:I$1000),"") | M18: =IF(OR(Registro!D17="Resuelto",Registro!D17=""),"",SUM(C18,F18,I18,L18)) | N18: =IF(OR(Registro!D17="Resuelto",Registro!D17=""),"",SUM(B18,E18,H18,K18)) | O18: =IF(OR(Registro!D17="Resuelto",Registro!D17=""),"",_xlfn.CONCAT(A18,D18,G18,J18)) | P18: 10 | Q18: =IF(ISNA(VLOOKUP(P18,$M$9:$O$1000,3,FALSE))=TRUE,"",VLOOKUP(P18,$M$9:$O$1000,3,FALSE)) -> 6418-PFIN-26 | R18: =IF(ISNA(VLOOKUP(P18,$M$9:$O$1000,2,FALSE))=TRUE,"",VLOOKUP(P18,$M$9:$O$1000,2,FALSE)) -> -8 | W18: =IF(X18="","",MAX($W$5:W17)+1) -> 5 | X18: =IF(Registro!M17="","",IF(COUNTIF($X$8:X17,Registro!M17)=0,Registro!M17,"")) -> Gestor 2 | Y18: =IF(ISNA(VLOOKUP(P18,$W$9:$X$1000,2,FALSE))=TRUE,"",VLOOKUP(P18,$W$9:$X$1000,2,FALSE))
A19: =IF(AND(Registro!D18="Abierto",Registro!E18="Urgente"),Registro!B18,"") | B19: =IF(AND(Registro!D18="Abierto",Registro!E18="Urgente"),TODAY()-Registro!R18,"") | C19: =IF(AND(Registro!D18="Abierto",Registro!E18="Urgente"),RANK(B19,$B$9:$B$1000,0)+COUNTIF($B$9:B19,B19)-1,"") | D19: =IF(AND(Registro!D18="Abierto",Registro!E18="Alta"),Registro!B18,"") | E19: =IF(AND(Registro!D18="Abierto",Registro!E18="Alta"),TODAY()-Registro!R18,"") | F19: =IF(AND(Registro!D18="Abierto",Registro!E18="Alta"),RANK(E19,$E$9:$E$1000,0)+COUNTIF($E$9:E19,E19)-1+MAX(C$5:C$1000),"") | G19: =IF(AND(Registro!D18="Abierto",Registro!E18="Media"),Registro!B18,"") | H19: =IF(AND(Registro!D18="Abierto",Registro!E18="Media"),TODAY()-Registro!R18,"") | I19: =IF(AND(Registro!D18="Abierto",Registro!E18="Media"),RANK(H19,$H$9:$H$1000,0)+COUNTIF($H$9:H19,H19)-1+MAX(C$5:C$1000,F$5:F$1000),"") | J19: =IF(AND(Registro!D18="Abierto",Registro!E18="Baja"),Registro!B18,"") | K19: =IF(AND(Registro!D18="Abierto",Registro!E18="Baja"),TODAY()-Registro!R18,"") | L19: =IF(AND(Registro!D18="Abierto",Registro!E18="Baja"),RANK(K19,$K$9:$K$1000,0)+COUNTIF($K$9:K19,K19)-1+MAX(C$5:C$1000,F$5:F$1000,I$5:I$1000),"") | M19: =IF(OR(Registro!D18="Resuelto",Registro!D18=""),"",SUM(C19,F19,I19,L19)) | N19: =IF(OR(Registro!D18="Resuelto",Registro!D18=""),"",SUM(B19,E19,H19,K19)) | O19: =IF(OR(Registro!D18="Resuelto",Registro!D18=""),"",_xlfn.CONCAT(A19,D19,G19,J19)) | P19: 11 | Q19: =IF(ISNA(VLOOKUP(P19,$M$9:$O$1000,3,FALSE))=TRUE,"",VLOOKUP(P19,$M$9:$O$1000,3,FALSE)) -> 6304-PFIN-26 | R19: =IF(ISNA(VLOOKUP(P19,$M$9:$O$1000,2,FALSE))=TRUE,"",VLOOKUP(P19,$M$9:$O$1000,2,FALSE)) -> 44 | W19: =IF(X19="","",MAX($W$5:W18)+1) | X19: =IF(Registro!M18="","",IF(COUNTIF($X$8:X18,Registro!M18)=0,Registro!M18,"")) | Y19: =IF(ISNA(VLOOKUP(P19,$W$9:$X$1000,2,FALSE))=TRUE,"",VLOOKUP(P19,$W$9:$X$1000,2,FALSE))
A20: =IF(AND(Registro!D19="Abierto",Registro!E19="Urgente"),Registro!B19,"") | B20: =IF(AND(Registro!D19="Abierto",Registro!E19="Urgente"),TODAY()-Registro!R19,"") | C20: =IF(AND(Registro!D19="Abierto",Registro!E19="Urgente"),RANK(B20,$B$9:$B$1000,0)+COUNTIF($B$9:B20,B20)-1,"") | D20: =IF(AND(Registro!D19="Abierto",Registro!E19="Alta"),Registro!B19,"") | E20: =IF(AND(Registro!D19="Abierto",Registro!E19="Alta"),TODAY()-Registro!R19,"") | F20: =IF(AND(Registro!D19="Abierto",Registro!E19="Alta"),RANK(E20,$E$9:$E$1000,0)+COUNTIF($E$9:E20,E20)-1+MAX(C$5:C$1000),"") | G20: =IF(AND(Registro!D19="Abierto",Registro!E19="Media"),Registro!B19,"") | H20: =IF(AND(Registro!D19="Abierto",Registro!E19="Media"),TODAY()-Registro!R19,"") | I20: =IF(AND(Registro!D19="Abierto",Registro!E19="Media"),RANK(H20,$H$9:$H$1000,0)+COUNTIF($H$9:H20,H20)-1+MAX(C$5:C$1000,F$5:F$1000),"") | J20: =IF(AND(Registro!D19="Abierto",Registro!E19="Baja"),Registro!B19,"") | K20: =IF(AND(Registro!D19="Abierto",Registro!E19="Baja"),TODAY()-Registro!R19,"") | L20: =IF(AND(Registro!D19="Abierto",Registro!E19="Baja"),RANK(K20,$K$9:$K$1000,0)+COUNTIF($K$9:K20,K20)-1+MAX(C$5:C$1000,F$5:F$1000,I$5:I$1000),"") | M20: =IF(OR(Registro!D19="Resuelto",Registro!D19=""),"",SUM(C20,F20,I20,L20)) -> 0 | N20: =IF(OR(Registro!D19="Resuelto",Registro!D19=""),"",SUM(B20,E20,H20,K20)) -> 0 | O20: =IF(OR(Registro!D19="Resuelto",Registro!D19=""),"",_xlfn.CONCAT(A20,D20,G20,J20)) | P20: 12 | Q20: =IF(ISNA(VLOOKUP(P20,$M$9:$O$1000,3,FALSE))=TRUE,"",VLOOKUP(P20,$M$9:$O$1000,3,FALSE)) -> 6305-PFIN-26 | R20: =IF(ISNA(VLOOKUP(P20,$M$9:$O$1000,2,FALSE))=TRUE,"",VLOOKUP(P20,$M$9:$O$1000,2,FALSE)) -> 44 | W20: =IF(X20="","",MAX($W$5:W19)+1) | X20: =IF(Registro!M19="","",IF(COUNTIF($X$8:X19,Registro!M19)=0,Registro!M19,"")) | Y20: =IF(ISNA(VLOOKUP(P20,$W$9:$X$1000,2,FALSE))=TRUE,"",VLOOKUP(P20,$W$9:$X$1000,2,FALSE))
A21: =IF(AND(Registro!D20="Abierto",Registro!E20="Urgente"),Registro!B20,"") | B21: =IF(AND(Registro!D20="Abierto",Registro!E20="Urgente"),TODAY()-Registro!R20,"") | C21: =IF(AND(Registro!D20="Abierto",Registro!E20="Urgente"),RANK(B21,$B$9:$B$1000,0)+COUNTIF($B$9:B21,B21)-1,"") | D21: =IF(AND(Registro!D20="Abierto",Registro!E20="Alta"),Registro!B20,"") | E21: =IF(AND(Registro!D20="Abierto",Registro!E20="Alta"),TODAY()-Registro!R20,"") | F21: =IF(AND(Registro!D20="Abierto",Registro!E20="Alta"),RANK(E21,$E$9:$E$1000,0)+COUNTIF($E$9:E21,E21)-1+MAX(C$5:C$1000),"") | G21: =IF(AND(Registro!D20="Abierto",Registro!E20="Media"),Registro!B20,"") | H21: =IF(AND(Registro!D20="Abierto",Registro!E20="Media"),TODAY()-Registro!R20,"") | I21: =IF(AND(Registro!D20="Abierto",Registro!E20="Media"),RANK(H21,$H$9:$H$1000,0)+COUNTIF($H$9:H21,H21)-1+MAX(C$5:C$1000,F$5:F$1000),"") | J21: =IF(AND(Registro!D20="Abierto",Registro!E20="Baja"),Registro!B20,"") | K21: =IF(AND(Registro!D20="Abierto",Registro!E20="Baja"),TODAY()-Registro!R20,"") | L21: =IF(AND(Registro!D20="Abierto",Registro!E20="Baja"),RANK(K21,$K$9:$K$1000,0)+COUNTIF($K$9:K21,K21)-1+MAX(C$5:C$1000,F$5:F$1000,I$5:I$1000),"") | M21: =IF(OR(Registro!D20="Resuelto",Registro!D20=""),"",SUM(C21,F21,I21,L21)) | N21: =IF(OR(Registro!D20="Resuelto",Registro!D20=""),"",SUM(B21,E21,H21,K21)) | O21: =IF(OR(Registro!D20="Resuelto",Registro!D20=""),"",_xlfn.CONCAT(A21,D21,G21,J21)) | P21: 13 | Q21: =IF(ISNA(VLOOKUP(P21,$M$9:$O$1000,3,FALSE))=TRUE,"",VLOOKUP(P21,$M$9:$O$1000,3,FALSE)) -> 6306-PFIN-26 | R21: =IF(ISNA(VLOOKUP(P21,$M$9:$O$1000,2,FALSE))=TRUE,"",VLOOKUP(P21,$M$9:$O$1000,2,FALSE)) -> 44 | W21: =IF(X21="","",MAX($W$5:W20)+1) | X21: =IF(Registro!M20="","",IF(COUNTIF($X$8:X20,Registro!M20)=0,Registro!M20,"")) | Y21: =IF(ISNA(VLOOKUP(P21,$W$9:$X$1000,2,FALSE))=TRUE,"",VLOOKUP(P21,$W$9:$X$1000,2,FALSE))
A22: =IF(AND(Registro!D21="Abierto",Registro!E21="Urgente"),Registro!B21,"") | B22: =IF(AND(Registro!D21="Abierto",Registro!E21="Urgente"),TODAY()-Registro!R21,"") | C22: =IF(AND(Registro!D21="Abierto",Registro!E21="Urgente"),RANK(B22,$B$9:$B$1000,0)+COUNTIF($B$9:B22,B22)-1,"") | D22: =IF(AND(Registro!D21="Abierto",Registro!E21="Alta"),Registro!B21,"") | E22: =IF(AND(Registro!D21="Abierto",Registro!E21="Alta"),TODAY()-Registro!R21,"") | F22: =IF(AND(Registro!D21="Abierto",Registro!E21="Alta"),RANK(E22,$E$9:$E$1000,0)+COUNTIF($E$9:E22,E22)-1+MAX(C$5:C$1000),"") | G22: =IF(AND(Registro!D21="Abierto",Registro!E21="Media"),Registro!B21,"") | H22: =IF(AND(Registro!D21="Abierto",Registro!E21="Media"),TODAY()-Registro!R21,"") | I22: =IF(AND(Registro!D21="Abierto",Registro!E21="Media"),RANK(H22,$H$9:$H$1000,0)+COUNTIF($H$9:H22,H22)-1+MAX(C$5:C$1000,F$5:F$1000),"") | J22: =IF(AND(Registro!D21="Abierto",Registro!E21="Baja"),Registro!B21,"") | K22: =IF(AND(Registro!D21="Abierto",Registro!E21="Baja"),TODAY()-Registro!R21,"") | L22: =IF(AND(Registro!D21="Abierto",Registro!E21="Baja"),RANK(K22,$K$9:$K$1000,0)+COUNTIF($K$9:K22,K22)-1+MAX(C$5:C$1000,F$5:F$1000,I$5:I$1000),"") | M22: =IF(OR(Registro!D21="Resuelto",Registro!D21=""),"",SUM(C22,F22,I22,L22)) | N22: =IF(OR(Registro!D21="Resuelto",Registro!D21=""),"",SUM(B22,E22,H22,K22)) | O22: =IF(OR(Registro!D21="Resuelto",Registro!D21=""),"",_xlfn.CONCAT(A22,D22,G22,J22)) | P22: 14 | Q22: =IF(ISNA(VLOOKUP(P22,$M$9:$O$1000,3,FALSE))=TRUE,"",VLOOKUP(P22,$M$9:$O$1000,3,FALSE)) -> 6348-PFIN-26 | R22: =IF(ISNA(VLOOKUP(P22,$M$9:$O$1000,2,FALSE))=TRUE,"",VLOOKUP(P22,$M$9:$O$1000,2,FALSE)) -> 6 | W22: =IF(X22="","",MAX($W$5:W21)+1) | X22: =IF(Registro!M21="","",IF(COUNTIF($X$8:X21,Registro!M21)=0,Registro!M21,"")) | Y22: =IF(ISNA(VLOOKUP(P22,$W$9:$X$1000,2,FALSE))=TRUE,"",VLOOKUP(P22,$W$9:$X$1000,2,FALSE))
A23: =IF(AND(Registro!D22="Abierto",Registro!E22="Urgente"),Registro!B22,"") | B23: =IF(AND(Registro!D22="Abierto",Registro!E22="Urgente"),TODAY()-Registro!R22,"") | C23: =IF(AND(Registro!D22="Abierto",Registro!E22="Urgente"),RANK(B23,$B$9:$B$1000,0)+COUNTIF($B$9:B23,B23)-1,"") | D23: =IF(AND(Registro!D22="Abierto",Registro!E22="Alta"),Registro!B22,"") | E23: =IF(AND(Registro!D22="Abierto",Registro!E22="Alta"),TODAY()-Registro!R22,"") | F23: =IF(AND(Registro!D22="Abierto",Registro!E22="Alta"),RANK(E23,$E$9:$E$1000,0)+COUNTIF($E$9:E23,E23)-1+MAX(C$5:C$1000),"") | G23: =IF(AND(Registro!D22="Abierto",Registro!E22="Media"),Registro!B22,"") | H23: =IF(AND(Registro!D22="Abierto",Registro!E22="Media"),TODAY()-Registro!R22,"") | I23: =IF(AND(Registro!D22="Abierto",Registro!E22="Media"),RANK(H23,$H$9:$H$1000,0)+COUNTIF($H$9:H23,H23)-1+MAX(C$5:C$1000,F$5:F$1000),"") | J23: =IF(AND(Registro!D22="Abierto",Registro!E22="Baja"),Registro!B22,"") | K23: =IF(AND(Registro!D22="Abierto",Registro!E22="Baja"),TODAY()-Registro!R22,"") | L23: =IF(AND(Registro!D22="Abierto",Registro!E22="Baja"),RANK(K23,$K$9:$K$1000,0)+COUNTIF($K$9:K23,K23)-1+MAX(C$5:C$1000,F$5:F$1000,I$5:I$1000),"") | M23: =IF(OR(Registro!D22="Resuelto",Registro!D22=""),"",SUM(C23,F23,I23,L23)) | N23: =IF(OR(Registro!D22="Resuelto",Registro!D22=""),"",SUM(B23,E23,H23,K23)) | O23: =IF(OR(Registro!D22="Resuelto",Registro!D22=""),"",_xlfn.CONCAT(A23,D23,G23,J23)) | P23: 15 | Q23: =IF(ISNA(VLOOKUP(P23,$M$9:$O$1000,3,FALSE))=TRUE,"",VLOOKUP(P23,$M$9:$O$1000,3,FALSE)) -> 6295-PFIN-26 | R23: =IF(ISNA(VLOOKUP(P23,$M$9:$O$1000,2,FALSE))=TRUE,"",VLOOKUP(P23,$M$9:$O$1000,2,FALSE)) -> -4 | W23: =IF(X23="","",MAX($W$5:W22)+1) | X23: =IF(Registro!M22="","",IF(COUNTIF($X$8:X22,Registro!M22)=0,Registro!M22,"")) | Y23: =IF(ISNA(VLOOKUP(P23,$W$9:$X$1000,2,FALSE))=TRUE,"",VLOOKUP(P23,$W$9:$X$1000,2,FALSE))
A24: =IF(AND(Registro!D23="Abierto",Registro!E23="Urgente"),Registro!B23,"") | B24: =IF(AND(Registro!D23="Abierto",Registro!E23="Urgente"),TODAY()-Registro!R23,"") | C24: =IF(AND(Registro!D23="Abierto",Registro!E23="Urgente"),RANK(B24,$B$9:$B$1000,0)+COUNTIF($B$9:B24,B24)-1,"") | D24: =IF(AND(Registro!D23="Abierto",Registro!E23="Alta"),Registro!B23,"") | E24: =IF(AND(Registro!D23="Abierto",Registro!E23="Alta"),TODAY()-Registro!R23,"") | F24: =IF(AND(Registro!D23="Abierto",Registro!E23="Alta"),RANK(E24,$E$9:$E$1000,0)+COUNTIF($E$9:E24,E24)-1+MAX(C$5:C$1000),"") | G24: =IF(AND(Registro!D23="Abierto",Registro!E23="Media"),Registro!B23,"") | H24: =IF(AND(Registro!D23="Abierto",Registro!E23="Media"),TODAY()-Registro!R23,"") | I24: =IF(AND(Registro!D23="Abierto",Registro!E23="Media"),RANK(H24,$H$9:$H$1000,0)+COUNTIF($H$9:H24,H24)-1+MAX(C$5:C$1000,F$5:F$1000),"") | J24: =IF(AND(Registro!D23="Abierto",Registro!E23="Baja"),Registro!B23,"") -> 6294-PFIN-26 | K24: =IF(AND(Registro!D23="Abierto",Registro!E23="Baja"),TODAY()-Registro!R23,"") -> 2 | L24: =IF(AND(Registro!D23="Abierto",Registro!E23="Baja"),RANK(K24,$K$9:$K$1000,0)+COUNTIF($K$9:K24,K24)-1+MAX(C$5:C$1000,F$5:F$1000,I$5:I$1000),"") -> 28 | M24: =IF(OR(Registro!D23="Resuelto",Registro!D23=""),"",SUM(C24,F24,I24,L24)) -> 28 | N24: =IF(OR(Registro!D23="Resuelto",Registro!D23=""),"",SUM(B24,E24,H24,K24)) -> 2 | O24: =IF(OR(Registro!D23="Resuelto",Registro!D23=""),"",_xlfn.CONCAT(A24,D24,G24,J24)) -> 6294-PFIN-26 | P24: 16 | Q24: =IF(ISNA(VLOOKUP(P24,$M$9:$O$1000,3,FALSE))=TRUE,"",VLOOKUP(P24,$M$9:$O$1000,3,FALSE)) -> 6374-PFIN-26 | R24: =IF(ISNA(VLOOKUP(P24,$M$9:$O$1000,2,FALSE))=TRUE,"",VLOOKUP(P24,$M$9:$O$1000,2,FALSE)) -> -6 | W24: =IF(X24="","",MAX($W$5:W23)+1) | X24: =IF(Registro!M23="","",IF(COUNTIF($X$8:X23,Registro!M23)=0,Registro!M23,"")) | Y24: =IF(ISNA(VLOOKUP(P24,$W$9:$X$1000,2,FALSE))=TRUE,"",VLOOKUP(P24,$W$9:$X$1000,2,FALSE))
A25: =IF(AND(Registro!D24="Abierto",Registro!E24="Urgente"),Registro!B24,"") | B25: =IF(AND(Registro!D24="Abierto",Registro!E24="Urgente"),TODAY()-Registro!R24,"") | C25: =IF(AND(Registro!D24="Abierto",Registro!E24="Urgente"),RANK(B25,$B$9:$B$1000,0)+COUNTIF($B$9:B25,B25)-1,"") | D25: =IF(AND(Registro!D24="Abierto",Registro!E24="Alta"),Registro!B24,"") | E25: =IF(AND(Registro!D24="Abierto",Registro!E24="Alta"),TODAY()-Registro!R24,"") | F25: =IF(AND(Registro!D24="Abierto",Registro!E24="Alta"),RANK(E25,$E$9:$E$1000,0)+COUNTIF($E$9:E25,E25)-1+MAX(C$5:C$1000),"") | G25: =IF(AND(Registro!D24="Abierto",Registro!E24="Media"),Registro!B24,"") | H25: =IF(AND(Registro!D24="Abierto",Registro!E24="Media"),TODAY()-Registro!R24,"") | I25: =IF(AND(Registro!D24="Abierto",Registro!E24="Media"),RANK(H25,$H$9:$H$1000,0)+COUNTIF($H$9:H25,H25)-1+MAX(C$5:C$1000,F$5:F$1000),"") | J25: =IF(AND(Registro!D24="Abierto",Registro!E24="Baja"),Registro!B24,"") | K25: =IF(AND(Registro!D24="Abierto",Registro!E24="Baja"),TODAY()-Registro!R24,"") | L25: =IF(AND(Registro!D24="Abierto",Registro!E24="Baja"),RANK(K25,$K$9:$K$1000,0)+COUNTIF($K$9:K25,K25)-1+MAX(C$5:C$1000,F$5:F$1000,I$5:I$1000),"") | M25: =IF(OR(Registro!D24="Resuelto",Registro!D24=""),"",SUM(C25,F25,I25,L25)) | N25: =IF(OR(Registro!D24="Resuelto",Registro!D24=""),"",SUM(B25,E25,H25,K25)) | O25: =IF(OR(Registro!D24="Resuelto",Registro!D24=""),"",_xlfn.CONCAT(A25,D25,G25,J25)) | P25: 17 | Q25: =IF(ISNA(VLOOKUP(P25,$M$9:$O$1000,3,FALSE))=TRUE,"",VLOOKUP(P25,$M$9:$O$1000,3,FALSE)) -> 6387-PFIN-26 | R25: =IF(ISNA(VLOOKUP(P25,$M$9:$O$1000,2,FALSE))=TRUE,"",VLOOKUP(P25,$M$9:$O$1000,2,FALSE)) -> -6 | W25: =IF(X25="","",MAX($W$5:W24)+1) | X25: =IF(Registro!M24="","",IF(COUNTIF($X$8:X24,Registro!M24)=0,Registro!M24,"")) | Y25: =IF(ISNA(VLOOKUP(P25,$W$9:$X$1000,2,FALSE))=TRUE,"",VLOOKUP(P25,$W$9:$X$1000,2,FALSE))
... A1000: =IF(AND(Registro!D999="Abierto",Registro!E999="Urgente"),Registro!B999,"") | B1000: =IF(AND(Registro!D999="Abierto",Registro!E999="Urgente"),TODAY()-Registro!R999,"") | C1000: =IF(AND(Registro!D999="Abierto",Registro!E999="Urgente"),RANK(B1000,$B$9:$B$1000,0)+COUNTIF($B$9:B1000,B1000)-1,"") | D1000: =IF(AND(Registro!D999="Abierto",Registro!E999="Alta"),Registro!B999,"") | E1000: =IF(AND(Registro!D999="Abierto",Registro!E999="Alta"),TODAY()-Registro!R999,"") | F1000: =IF(AND(Registro!D999="Abierto",Registro!E999="Alta"),RANK(E1000,$E$9:$E$1000,0)+COUNTIF($E$9:E1000,E1000)-1+MAX(C$5:C$1000),"") | G1000: =IF(AND(Registro!D999="Abierto",Registro!E999="Media"),Registro!B999,"") | H1000: =IF(AND(Registro!D999="Abierto",Registro!E999="Media"),TODAY()-Registro!R999,"") | I1000: =IF(AND(Registro!D999="Abierto",Registro!E999="Media"),RANK(H1000,$H$9:$H$1000,0)+COUNTIF($H$9:H1000,H1000)-1+MAX(C$5:C$1000,F$5:F$1000),"") | J1000: =IF(AND(Registro!D999="Abierto",Registro!E999="Baja"),Registro!B999,"") | K1000: =IF(AND(Registro!D999="Abierto",Registro!E999="Baja"),TODAY()-Registro!R999,"") | L1000: =IF(AND(Registro!D999="Abierto",Registro!E999="Baja"),RANK(K1000,$K$9:$K$1000,0)+COUNTIF($K$9:K1000,K1000)-1+MAX(C$5:C$1000,F$5:F$1000,I$5:I$1000),"") | M1000: =IF(OR(Registro!D999="Resuelto",Registro!D999=""),"",SUM(C1000,F1000,I1000,L1000)) | N1000: =IF(OR(Registro!D999="Resuelto",Registro!D999=""),"",SUM(B1000,E1000,H1000,K1000)) | O1000: =IF(OR(Registro!D999="Resuelto",Registro!D999=""),"",_xlfn.CONCAT(A1000,D1000,G1000,J1000)) | P1000: 992 | Q1000: =IF(ISNA(VLOOKUP(P1000,$M$9:$O$1000,3,FALSE))=TRUE,"",VLOOKUP(P1000,$M$9:$O$1000,3,FALSE)) | R1000: =IF(ISNA(VLOOKUP(P1000,$M$9:$O$1000,2,FALSE))=TRUE,"",VLOOKUP(P1000,$M$9:$O$1000,2,FALSE)) | W1000: =IF(X1000="","",MAX($W$5:W999)+1) | X1000: =IF(Registro!M999="","",IF(COUNTIF($X$8:X999,Registro!M999)=0,Registro!M999,"")) | Y1000: =IF(ISNA(VLOOKUP(P1000,$W$9:$X$1000,2,FALSE))=TRUE,"",VLOOKUP(P1000,$W$9:$X$1000,2,FALSE))

Sheet Listas
A1: Nombres
A2: Gestor 1
A3: Gestor 2
A4: Gestor 3
A5: Gestor 4
A6: Gestor 5
A9: Modalidad
A10: Presencial
A11: Virtual Sincrónico
A12: Virtual Asincrónico
A13: Mixto
A15: Dependencias
... A57: Mixto

Sheet Registro
B1: Control de Ejecución de Eventos Formativos
B7: Ticket # | C7: Link del Ticket | D7: Estado | E7: Prioridad | F7: Tipo de evento | G7: Programa | H7: Evento Formativo según PFA / Extraordinario | I7: Trasladado por: | J7: Fecha de ingreso | K7: Dependencia | L7: Fecha de Asignación | M7: Asignado a: | N7: Código de insumo | O7: Nombre del código de insumo | P7: Requisición | Q7: Costo Docente | R7: Inicio del Evento | S7: Fin del Evento | T7: R/N | U7: Grupos programados | V7: Sesiones por grupo | W7: Grupos Atendidos | X7: Grupos No Iniciados | Y7: Grupos en proceso | Z7: Total de sesiones | AA7: Sesiones terminadas | AB7: Sesiones faltantes | AC7: Tipo docente | AD7: Observaciones
B8: 6262-PFIN-26 | C8: https://sistema-eventos.edu.gt/ticket?id=8 | D8: Resuelto | E8: Baja | F8: Virtual Sincrónico | H8: Curso 1 | I8: Mesa de Entrada | J8: 46226.626 | K8: Dependencia 8 | L8: 46227.59 | M8: Gestor 1 | R8: 46272 | S8: 46275 | T8: =IF(U8="","",IF(U8=W8,1,0)) -> 1 | U8: 2 | V8: 2 | W8: =IF(B8="","",COUNTIFS(Ejecucion[No. Solicitud],Registro!B8,Ejecucion[Estado],"Finalizado")) -> 2 | X8: =IF(B8="","",COUNTIFS(Ejecucion[No. Solicitud],Registro!B8,Ejecucion[Estado],"No Iniciado")) -> 0 | Y8: =IF(B8="","",COUNTIFS(Ejecucion[No. Solicitud],Registro!B8,Ejecucion[Estado],"En Proceso")) -> 0 | Z8: =IF(U8="","",IF(F8="Virtual Asincrónico",1,V8*U8)) -> 4 | AC8: Cooperante | AD8: CAMBIO DINÁMICO: Interno a Externo
B9: 6261-PFIN-26 | C9: https://sistema-eventos.edu.gt/ticket?id=9 | D9: Resuelto | E9: Baja | F9: Virtual Asincrónico | H9: Curso 2 | I9: Mesa de Entrada | J9: 46225.41 | K9: Varias Dependencias | L9: 46227.602 | M9: Gestor 4 | R9: 46259 | S9: 46265 | T9: =IF(U9="","",IF(U9=W9,1,0)) -> 0 | U9: 2 | V9: 2 | W9: =IF(B9="","",COUNTIFS(Ejecucion[No. Solicitud],Registro!B9,Ejecucion[Estado],"Finalizado")) -> 1 | X9: =IF(B9="","",COUNTIFS(Ejecucion[No. Solicitud],Registro!B9,Ejecucion[Estado],"No Iniciado")) -> 0 | Y9: =IF(B9="","",COUNTIFS(Ejecucion[No. Solicitud],Registro!B9,Ejecucion[Estado],"En Proceso")) -> 0 | Z9: =IF(U9="","",IF(F9="Virtual Asincrónico",1,V9*U9)) -> 1 | AC9: Interno | AD9: TRASLADO A DFV - Ruta B
B10: 6275-PFIN-26 | C10: https://sistema-eventos.edu.gt/ticket?id=10 | D10: Resuelto | E10: Baja | F10: Presencial | H10: Curso 3 | I10: Mesa de Entrada | J10: 46234.672 | K10: Varias Dependencias | L10: 46237.353 | M10: Gestor 5 | R10: 46246 | S10: 46247 | T10: =IF(U10="","",IF(U10=W10,1,0)) -> 1 | U10: 2 | V10: 1 | W10: =IF(B10="","",COUNTIFS(Ejecucion[No. Solicitud],Registro!B10,Ejecucion[Estado],"Finalizado")) -> 2 | X10: 1 | Y10: 1 | Z10: =IF(U10="","",IF(F10="Virtual Asincrónico",1,V10*U10)) -> 2 | AA10: 1 | AB10: 1 | AC10: Interno | AD10: OBLIGATORIO - Docente Nuevo
B11: 6276-PFIN-26 | C11: https://sistema-eventos.edu.gt/ticket?id=11 | D11: Resuelto | E11: Baja | F11: Presencial | H11: Curso 4 | I11: Mesa de Entrada | J11: 46237.407 | K11: Dependencia 4 | L11: 46237.442 | M11: Gestor 3 | N11: 167663 | O11: Capacitación sobre detección de mentiras en la entrevista laboral | P11: 26-17046 | R11: 46261 | S11: 46275 | T11: =IF(U11="","",IF(U11=W11,1,0)) -> 1 | U11: 2 | V11: 2 | W11: =IF(B11="","",COUNTIFS(Ejecucion[No. Solicitud],Registro!B11,Ejecucion[Estado],"Finalizado")) -> 2 | X11: =IF(B11="","",COUNTIFS(Ejecucion[No. Solicitud],Registro!B11,Ejecucion[Estado],"No Iniciado")) -> 0 | Y11: =IF(B11="","",COUNTIFS(Ejecucion[No. Solicitud],Registro!B11,Ejecucion[Estado],"En Proceso")) -> 0 | Z11: =IF(U11="","",IF(F11="Virtual Asincrónico",1,V11*U11)) -> 4 | AC11: Externo | AD11: OBLIGATORIO - Docente Nuevo
B12: 6278-PFIN-26 | C12: https://sistema-eventos.edu.gt/ticket?id=12 | D12: Resuelto | E12: Baja | F12: Presencial | H12: Curso 5 | I12: Mesa de Entrada | J12: 46237.595 | K12: Dependencia 4 | L12: 46238.394 | M12: Gestor 5 | R12: 46274 | S12: 46275 | T12: =IF(U12="","",IF(U12=W12,1,0)) -> 1 | U12: 2 | V12: 2 | W12: =IF(B12="","",COUNTIFS(Ejecucion[No. Solicitud],Registro!B12,Ejecucion[Estado],"Finalizado")) -> 2 | X12: =IF(B12="","",COUNTIFS(Ejecucion[No. Solicitud],Registro!B12,Ejecucion[Estado],"No Iniciado")) -> 0 | Y12: =IF(B12="","",COUNTIFS(Ejecucion[No. Solicitud],Registro!B12,Ejecucion[Estado],"En Proceso")) -> 0 | Z12: =IF(U12="","",IF(F12="Virtual Asincrónico",1,V12*U12)) -> 4 | AC12: Interno | AD12: CAMBIO DINÁMICO: Interno a Externo
B13: 6281-PFIN-26 | C13: https://sistema-eventos.edu.gt/ticket?id=13 | D13: Abierto | E13: Baja | F13: Virtual Sincrónico | H13: Curso 6 | I13: Mesa de Entrada | J13: 46238.34 | K13: Dependencia 4 | L13: 46238.44 | M13: Gestor 3 | N13: 194323 | O13: Capacitación sobre el tema investigaciones internas forense corporativo | P13: 26-18548. | Q13: 10500 | R13: 46308 | S13: 46325 | T13: =IF(U13="","",IF(U13=W13,1,0)) -> 0 | U13: 2 | V13: 3 | W13: =IF(B13="","",COUNTIFS(Ejecucion[No. Solicitud],Registro!B13,Ejecucion[Estado],"Finalizado")) -> 0 | X13: =IF(B13="","",COUNTIFS(Ejecucion[No. Solicitud],Registro!B13,Ejecucion[Estado],"No Iniciado")) -> 0 | Y13: =IF(B13="","",COUNTIFS(Ejecucion[No. Solicitud],Registro!B13,Ejecucion[Estado],"En Proceso")) -> 2 | Z13: =IF(U13="","",IF(F13="Virtual Asincrónico",1,V13*U13)) -> 6 | AC13: Externo | AD13: OBLIGATORIO - Tema Nuevo
B14: 6283-PFIN-26 | C14: https://sistema-eventos.edu.gt/ticket?id=14 | D14: Abierto | E14: Baja | F14: Virtual Sincrónico | H14: Curso 7 | I14: Mesa de Entrada | J14: 46238.416 | K14: Varias Dependencias | L14: 46238.44 | M14: Gestor 4 | R14: 46304 | S14: 46311 | T14: =IF(U14="","",IF(U14=W14,1,0)) -> 0 | U14: 1 | V14: 2 | W14: =IF(B14="","",COUNTIFS(Ejecucion[No. Solicitud],Registro!B14,Ejecucion[Estado],"Finalizado")) -> 0 | X14: =IF(B14="","",COUNTIFS(Ejecucion[No. Solicitud],Registro!B14,Ejecucion[Estado],"No Iniciado")) -> 0 | Y14: =IF(B14="","",COUNTIFS(Ejecucion[No. Solicitud],Registro!B14,Ejecucion[Estado],"En Proceso")) -> 1 | Z14: =IF(U14="","",IF(F14="Virtual Asincrónico",1,V14*U14)) -> 2 | AC14: Cooperante | AD14: OBLIGATORIO - Primera Vez
B15: 6284-PFIN-26 | C15: https://sistema-eventos.edu.gt/ticket?id=15 | D15: Abierto | E15: Baja | F15: Virtual Sincrónico | H15: Curso 8 | I15: Mesa de Entrada | J15: 46238.419 | K15: Dependencia 4 | L15: 46238.441 | M15: Gestor 1 | N15: 201376 | O15: Capacitación sobre el tema análisis socioeconómico financiero | P15: 26-21929 | R15: 46329 | S15: 46332 | T15: =IF(U15="","",IF(U15=W15,1,0)) -> 0 | U15: 2 | V15: 2 | W15: =IF(B15="","",COUNTIFS(Ejecucion[No. Solicitud],Registro!B15,Ejecucion[Estado],"Finalizado")) -> 0 | X15: =IF(B15="","",COUNTIFS(Ejecucion[No. Solicitud],Registro!B15,Ejecucion[Estado],"No Iniciado")) -> 0 | Y15: =IF(B15="","",COUNTIFS(Ejecucion[No. Solicitud],Registro!B15,Ejecucion[Estado],"En Proceso")) -> 2 | Z15: =IF(U15="","",IF(F15="Virtual Asincrónico",1,V15*U15)) -> 4 | AC15: Externo | AD15: OBLIGATORIO - Primera Vez
B16: 6286-PFIN-26 | C16: https://sistema-eventos.edu.gt/ticket?id=16 | D16: Abierto | E16: Baja | F16: Virtual Asincrónico | H16: Curso 9 | I16: Mesa de Entrada | J16: 46240.388 | K16: Dependencia 4 | L16: 46240.625 | M16: Gestor 4 | P16: 26-18209 | R16: 46350 | S16: 46356 | T16: =IF(U16="","",IF(U16=W16,1,0)) -> 0 | U16: 1 | V16: 5 | W16: =IF(B16="","",COUNTIFS(Ejecucion[No. Solicitud],Registro!B16,Ejecucion[Estado],"Finalizado")) -> 0 | X16: =IF(B16="","",COUNTIFS(Ejecucion[No. Solicitud],Registro!B16,Ejecucion[Estado],"No Iniciado")) -> 0 | Y16: =IF(B16="","",COUNTIFS(Ejecucion[No. Solicitud],Registro!B16,Ejecucion[Estado],"En Proceso")) -> 1 | Z16: =IF(U16="","",IF(F16="Virtual Asincrónico",1,V16*U16)) -> 1 | AC16: Interno | AD16: TRASLADO A DFV - Ruta B
B17: 6288-PFIN-26 | C17: https://sistema-eventos.edu.gt/ticket?id=17 | D17: Resuelto | E17: Baja | F17: Presencial | H17: Curso 10 | I17: Mesa de Entrada | J17: 46241.464 | K17: Varias Dependencias | L17: 46240.626 | M17: Gestor 2 | N17: 80994 | O17: Capacitación sobre el manejo de bizagi (modelo y notación de procesos de negocio) | P17: 26-17547 | Q17: 14336 | R17: 46282 | S17: 46283 | T17: =IF(U17="","",IF(U17=W17,1,0)) -> 1 | U17: 2 | V17: 1 | W17: =IF(B17="","",COUNTIFS(Ejecucion[No. Solicitud],Registro!B17,Ejecucion[Estado],"Finalizado")) -> 2 | X17: =IF(B17="","",COUNTIFS(Ejecucion[No. Solicitud],Registro!B17,Ejecucion[Estado],"No Iniciado")) -> 0 | Y17: =IF(B17="","",COUNTIFS(Ejecucion[No. Solicitud],Registro!B17,Ejecucion[Estado],"En Proceso")) -> 0 | Z17: =IF(U17="","",IF(F17="Virtual Asincrónico",1,V17*U17)) -> 2 | AC17: Externo | AD17: OBLIGATORIO - Primera Vez
B18: 6282-PFIN-26 | C18: https://sistema-eventos.edu.gt/ticket?id=18 | D18: Resuelto | E18: Alta | F18: Presencial | H18: Curso 11 | I18: Mesa de Entrada | J18: 46240.299 | K18: Varias Dependencias | L18: 46240.628 | M18: Gestor 5 | N18: 201374 | O18: Capacitación sobre el tema identificación de documentos falsos | P18: 26-18481 | R18: 46262 | S18: 46262 | T18: =IF(U18="","",IF(U18=W18,1,0)) -> 0 | U18: 1 | V18: 1 | W18: =IF(B18="","",COUNTIFS(Ejecucion[No. Solicitud],Registro!B18,Ejecucion[Estado],"Finalizado")) -> 0 | X18: =IF(B18="","",COUNTIFS(Ejecucion[No. Solicitud],Registro!B18,Ejecucion[Estado],"No Iniciado")) -> 0 | Y18: =IF(B18="","",COUNTIFS(Ejecucion[No. Solicitud],Registro!B18,Ejecucion[Estado],"En Proceso")) -> 1 | Z18: =IF(U18="","",IF(F18="Virtual Asincrónico",1,V18*U18)) -> 1 | AC18: Externo | AD18: CAMBIO DINÁMICO: Interno a Externo
B19: 6289-PFIN-26 | C19: https://sistema-eventos.edu.gt/ticket?id=19 | D19: Cancelado | E19: Baja | F19: Presencial | H19: Curso 12 | I19: Mesa de Entrada | J19: 46240.619 | K19: Varias Dependencias | L19: 46240.63 | M19: Gestor 5 | N19: 117594 | O19: Capacitación para integración de equipos de alto desempeño | P19: 26-17574 | R19: 46308 | S19: 46318 | T19: =IF(U19="","",IF(U19=W19,1,0)) -> 0 | U19: 5 | V19: 1 | W19: =IF(B19="","",COUNTIFS(Ejecucion[No. Solicitud],Registro!B19,Ejecucion[Estado],"Finalizado")) -> 0 | X19: =IF(B19="","",COUNTIFS(Ejecucion[No. Solicitud],Registro!B19,Ejecucion[Estado],"No Iniciado")) -> 0 | Y19: =IF(B19="","",COUNTIFS(Ejecucion[No. Solicitud],Registro!B19,Ejecucion[Estado],"En Proceso")) -> 0 | Z19: =IF(U19="","",IF(F19="Virtual Asincrónico",1,V19*U19)) -> 5 | AC19: Externo | AD19: OBLIGATORIO - Docente Nuevo
B20: 6290-PFIN-26 | C20: https://sistema-eventos.edu.gt/ticket?id=20 | D20: Resuelto | E20: Media | F20: Presencial | H20: Curso 13 | I20: Mesa de Entrada | J20: 46240.66 | K20: Varias Dependencias | L20: 46241.354 | M20: Gestor 4 | R20: 46268 | S20: 46275 | T20: =IF(U20="","",IF(U20=W20,1,0)) -> 1 | U20: 2 | V20: 1 | W20: =IF(B20="","",COUNTIFS(Ejecucion[No. Solicitud],Registro!B20,Ejecucion[Estado],"Finalizado")) -> 2 | X20: =IF(B20="","",COUNTIFS(Ejecucion[No. Solicitud],Registro!B20,Ejecucion[Estado],"No Iniciado")) -> 0 | Y20: =IF(B20="","",COUNTIFS(Ejecucion[No. Solicitud],Registro!B20,Ejecucion[Estado],"En Proceso")) -> 0 | Z20: =IF(U20="","",IF(F20="Virtual Asincrónico",1,V20*U20)) -> 2 | AC20: Interno | AD20: CAMBIO DINÁMICO: Interno a Externo
B21: 6291-PFIN-26 | C21: https://sistema-eventos.edu.gt/ticket?id=21 | D21: Resuelto | E21: Media | F21: Presencial | H21: Curso 14 | I21: Mesa de Entrada | J21: 46240.673 | K21: Varias Dependencias | L21: 46241.355 | M21: Gestor 3 | R21: 46272 | S21: 46272 | T21: =IF(U21="","",IF(U21=W21,1,0)) -> 1 | U21: 1 | V21: 1 | W21: =IF(B21="","",COUNTIFS(Ejecucion[No. Solicitud],Registro!B21,Ejecucion[Estado],"Finalizado")) -> 1 | X21: =IF(B21="","",COUNTIFS(Ejecucion[No. Solicitud],Registro!B21,Ejecucion[Estado],"No Iniciado")) -> 0 | Y21: =IF(B21="","",COUNTIFS(Ejecucion[No. Solicitud],Registro!B21,Ejecucion[Estado],"En Proceso")) -> 0 | Z21: =IF(U21="","",IF(F21="Virtual Asincrónico",1,V21*U21)) -> 1 | AC21: Interno | AD21: CAMBIO DINÁMICO: Interno a Externo
B22: 6292-PFIN-26 | C22: https://sistema-eventos.edu.gt/ticket?id=22 | D22: Resuelto | E22: Media | F22: Presencial | H22: Curso 15 | I22: Mesa de Entrada | J22: 46241.499 | K22: Dependencia 1 | L22: 46241.552 | M22: Gestor 4 | R22: 46272 | S22: 46273 | T22: =IF(U22="","",IF(U22=W22,1,0)) -> 1 | U22: 2 | V22: 1 | W22: =IF(B22="","",COUNTIFS(Ejecucion[No. Solicitud],Registro!B22,Ejecucion[Estado],"Finalizado")) -> 2 | X22: =IF(B22="","",COUNTIFS(Ejecucion[No. Solicitud],Registro!B22,Ejecucion[Estado],"No Iniciado")) -> 0 | Y22: =IF(B22="","",COUNTIFS(Ejecucion[No. Solicitud],Registro!B22,Ejecucion[Estado],"En Proceso")) -> 0 | Z22: =IF(U22="","",IF(F22="Virtual Asincrónico",1,V22*U22)) -> 2 | AC22: Interno | AD22: REGULAR - Muestreo Aleatorio
B23: 6294-PFIN-26 | C23: https://sistema-eventos.edu.gt/ticket?id=23 | D23: Abierto | E23: Baja | F23: Presencial | H23: Curso 16 | I23: Mesa de Entrada | J23: 46241.565 | K23: Varias Dependencias | L23: 46241.57 | M23: Gestor 3 | N23: 194323 | O23: Curso de Alto Desempeño y Protocolo | P23: 26-17535 | R23: 46308 | S23: 46324 | T23: =IF(U23="","",IF(U23=W23,1,0)) -> 0 | U23: 3 | V23: 2 | W23: =IF(B23="","",COUNTIFS(Ejecucion[No. Solicitud],Registro!B23,Ejecucion[Estado],"Finalizado")) -> 0 | X23: =IF(B23="","",COUNTIFS(Ejecucion[No. Solicitud],Registro!B23,Ejecucion[Estado],"No Iniciado")) -> 0 | Y23: =IF(B23="","",COUNTIFS(Ejecucion[No. Solicitud],Registro!B23,Ejecucion[Estado],"En Proceso")) -> 3 | Z23: =IF(U23="","",IF(F23="Virtual Asincrónico",1,V23*U23)) -> 6 | AC23: Externo | AD23: OBLIGATORIO - Docente Nuevo
B24: 6296-EXTNN-26 | C24: https://sistema-eventos.edu.gt/ticket?id=24 | D24: Resuelto | E24: Urgente | F24: Virtual Sincrónico | H24: Curso 17 | I24: Mesa de Entrada | J24: 46241.59 | K24: Varias Dependencias | L24: 46241.615 | M24: Gestor 3 | R24: 46246 | S24: 46247 | T24: =IF(U24="","",IF(U24=W24,1,0)) -> 0 | U24: 1 | V24: 2 | W24: =IF(B24="","",COUNTIFS(Ejecucion[No. Solicitud],Registro!B24,Ejecucion[Estado],"Finalizado")) -> 0 | X24: =IF(B24="","",COUNTIFS(Ejecucion[No. Solicitud],Registro!B24,Ejecucion[Estado],"No Iniciado")) -> 0 | Y24: =IF(B24="","",COUNTIFS(Ejecucion[No. Solicitud],Registro!B24,Ejecucion[Estado],"En Proceso")) -> 1 | Z24: =IF(U24="","",IF(F24="Virtual Asincrónico",1,V24*U24)) -> 2 | AC24: Interno | AD24: REGULAR - Muestreo Aleatorio
B25: 6297-PFIN-26 | C25: https://sistema-eventos.edu.gt/ticket?id=25 | D25: Abierto | E25: Baja | F25: Presencial | H25: Curso 18 | I25: Mesa de Entrada | J25: 46241.597 | K25: Varias Dependencias | L25: 46241.615 | M25: Gestor 1 | N25: 130088 | O25: Curso sobre las herramientas y procedimientos para medición de combustible | P25: 26-17544 | R25: 46300 | S25: 46308 | T25: =IF(U25="","",IF(U25=W25,1,0)) -> 0 | U25: 2 | V25: 2 | W25: =IF(B25="","",COUNTIFS(Ejecucion[No. Solicitud],Registro!B25,Ejecucion[Estado],"Finalizado")) -> 0 | X25: =IF(B25="","",COUNTIFS(Ejecucion[No. Solicitud],Registro!B25,Ejecucion[Estado],"No Iniciado")) -> 0 | Y25: =IF(B25="","",COUNTIFS(Ejecucion[No. Solicitud],Registro!B25,Ejecucion[Estado],"En Proceso")) -> 2 | Z25: =IF(U25="","",IF(F25="Virtual Asincrónico",1,V25*U25)) -> 4 | AC25: Externo | AD25: REGULAR - Muestreo Aleatorio
B26: 6295-PFIN-26 | C26: https://sistema-eventos.edu.gt/ticket?id=26 | D26: Abierto | E26: Media | F26: Presencial | H26: Curso 19 | I26: Mesa de Entrada | J26: 46241.578 | K26: Varias Dependencias | L26: 46282.384 | M26: Gestor 5 | R26: 46314 | S26: 46321 | T26: =IF(U26="","",IF(U26=W26,1,0)) -> 0 | U26: 2 | V26: 1 | W26: =IF(B26="","",COUNTIFS(Ejecucion[No. Solicitud],Registro!B26,Ejecucion[Estado],"Finalizado")) -> 0 | X26: =IF(B26="","",COUNTIFS(Ejecucion[No. Solicitud],Registro!B26,Ejecucion[Estado],"No Iniciado")) -> 0 | Y26: =IF(B26="","",COUNTIFS(Ejecucion[No. Solicitud],Registro!B26,Ejecucion[Estado],"En Proceso")) -> 2 | Z26: =IF(U26="","",IF(F26="Virtual Asincrónico",1,V26*U26)) -> 2 | AC26: Interno | AD26: OBLIGATORIO - Docente Nuevo
B27: 6298-PFIN-26 | C27: https://sistema-eventos.edu.gt/ticket?id=27 | D27: Resuelto | E27: Media | F27: Presencial | H27: Curso 20 | I27: Mesa de Entrada | J27: 46244.369 | K27: Varias Dependencias | L27: 46244.485 | M27: Gestor 4 | R27: 46287 | S27: 46288 | T27: =IF(U27="","",IF(U27=W27,1,0)) -> 1 | U27: 2 | V27: 1 | W27: =IF(B27="","",COUNTIFS(Ejecucion[No. Solicitud],Registro!B27,Ejecucion[Estado],"Finalizado")) -> 2 | X27: =IF(B27="","",COUNTIFS(Ejecucion[No. Solicitud],Registro!B27,Ejecucion[Estado],"No Iniciado")) -> 0 | Y27: =IF(B27="","",COUNTIFS(Ejecucion[No. Solicitud],Registro!B27,Ejecucion[Estado],"En Proceso")) -> 0 | Z27: =IF(U27="","",IF(F27="Virtual Asincrónico",1,V27*U27)) -> 2 | AC27: Interno | AD27: OBLIGATORIO - Docente Nuevo
B28: 6299-PFIN-26 | C28: https://sistema-eventos.edu.gt/ticket?id=28 | D28: Abierto | E28: Baja | F28: Presencial | H28: Curso 21 | I28: Mesa de Entrada | J28: 46244.458 | K28: Varias Dependencias | L28: 46244.483 | M28: Gestor 2 | N28: 199042 | O28: Capacitación sobre el tema de curso de casos prácticos sobre la determinación del impuesto sobre la renta en empresas productoras de café | P28: 26-18209 | R28: 46310 | S28: 46311 | T28: =IF(U28="","",IF(U28=W28,1,0)) -> 0 | U28: 2 | V28: 1 | W28: =IF(B28="","",COUNTIFS(Ejecucion[No. Solicitud],Registro!B28,Ejecucion[Estado],"Finalizado")) -> 0 | X28: =IF(B28="","",COUNTIFS(Ejecucion[No. Solicitud],Registro!B28,Ejecucion[Estado],"No Iniciado")) -> 0 | Y28: =IF(B28="","",COUNTIFS(Ejecucion[No. Solicitud],Registro!B28,Ejecucion[Estado],"En Proceso")) -> 2 | Z28: =IF(U28="","",IF(F28="Virtual Asincrónico",1,V28*U28)) -> 2 | AC28: Cooperante | AD28: OBLIGATORIO - Docente Nuevo
B29: 6304-PFIN-26 | C29: https://sistema-eventos.edu.gt/ticket?id=29 | D29: Abierto | E29: Media | F29: Virtual Asincrónico | H29: Curso 22 | I29: Mesa de Entrada | J29: 46245.349 | K29: Varias Dependencias | L29: 46245.452 | M29: Gestor 4 | R29: 46266 | S29: 46266 | T29: =IF(U29="","",IF(U29=W29,1,0)) -> 0 | U29: 1 | V29: 5 | W29: =IF(B29="","",COUNTIFS(Ejecucion[No. Solicitud],Registro!B29,Ejecucion[Estado],"Finalizado")) -> 0 | X29: =IF(B29="","",COUNTIFS(Ejecucion[No. Solicitud],Registro!B29,Ejecucion[Estado],"No Iniciado")) -> 0 | Y29: =IF(B29="","",COUNTIFS(Ejecucion[No. Solicitud],Registro!B29,Ejecucion[Estado],"En Proceso")) -> 0 | Z29: =IF(U29="","",IF(F29="Virtual Asincrónico",1,V29*U29)) -> 1 | AC29: Interno | AD29: TRASLADO A DFV - Ruta B
B30: 6305-PFIN-26 | C30: https://sistema-eventos.edu.gt/ticket?id=30 | D30: Abierto | E30: Media | F30: Virtual Asincrónico | H30: Curso 23 | I30: Mesa de Entrada | J30: 46245.349 | K30: Varias Dependencias | L30: 46245.453 | M30: Gestor 4 | R30: 46266 | S30: 46266 | T30: =IF(U30="","",IF(U30=W30,1,0)) -> 0 | U30: 1 | V30: 5 | W30: =IF(B30="","",COUNTIFS(Ejecucion[No. Solicitud],Registro!B30,Ejecucion[Estado],"Finalizado")) -> 0 | X30: =IF(B30="","",COUNTIFS(Ejecucion[No. Solicitud],Registro!B30,Ejecucion[Estado],"No Iniciado")) -> 0 | Y30: =IF(B30="","",COUNTIFS(Ejecucion[No. Solicitud],Registro!B30,Ejecucion[Estado],"En Proceso")) -> 0 | Z30: =IF(U30="","",IF(F30="Virtual Asincrónico",1,V30*U30)) -> 1 | AC30: Interno | AD30: TRASLADO A DFV - Ruta B
B31: 6306-PFIN-26 | C31: https://sistema-eventos.edu.gt/ticket?id=31 | D31: Abierto | E31: Media | F31: Virtual Asincrónico | H31: Curso 24 | I31: Mesa de Entrada | J31: 46245.351 | K31: Varias Dependencias | L31: 46245.453 | M31: Gestor 4 | R31: 46266 | S31: 46266 | T31: =IF(U31="","",IF(U31=W31,1,0)) -> 0 | U31: 1 | V31: 5 | W31: =IF(B31="","",COUNTIFS(Ejecucion[No. Solicitud],Registro!B31,Ejecucion[Estado],"Finalizado")) -> 0 | X31: =IF(B31="","",COUNTIFS(Ejecucion[No. Solicitud],Registro!B31,Ejecucion[Estado],"No Iniciado")) -> 0 | Y31: =IF(B31="","",COUNTIFS(Ejecucion[No. Solicitud],Registro!B31,Ejecucion[Estado],"En Proceso")) -> 0 | Z31: =IF(U31="","",IF(F31="Virtual Asincrónico",1,V31*U31)) -> 1 | AC31: Cooperante | AD31: TRASLADO A DFV - Ruta B
B32: 6312-PFIN-26 | C32: https://sistema-eventos.edu.gt/ticket?id=32 | D32: Resuelto | E32: Baja | F32: Presencial | H32: Curso 25 | I32: Mesa de Entrada | J32: 46251.311 | K32: Dependencia 3 | L32: 46251.334 | M32: Gestor 1 | N32: 110089 | O32: Capacitación en redes y telecomunicaciones | P32: 26-18204 | Q32: 8000 | R32: 46287 | S32: 46287 | T32: =IF(U32="","",IF(U32=W32,1,0)) -> 1 | U32: 1 | V32: 1 | W32: =IF(B32="","",COUNTIFS(Ejecucion[No. Solicitud],Registro!B32,Ejecucion[Estado],"Finalizado")) -> 1 | X32: =IF(B32="","",COUNTIFS(Ejecucion[No. Solicitud],Registro!B32,Ejecucion[Estado],"No Iniciado")) -> 0 | Y32: =IF(B32="","",COUNTIFS(Ejecucion[No. Solicitud],Registro!B32,Ejecucion[Estado],"En Proceso")) -> 0 | Z32: =IF(U32="","",IF(F32="Virtual Asincrónico",1,V32*U32)) -> 1 | AC32: Cooperante | AD32: OBLIGATORIO - Docente Nuevo
B33: 6313-PFIN-26 | C33: https://sistema-eventos.edu.gt/ticket?id=33 | D33: Abierto | E33: Baja | F33: Virtual Asincrónico | H33: Curso 26 | I33: Mesa de Entrada | J33: 46251.344 | K33: Varias Dependencias | L33: 46251.345 | M33: Gestor 5 | N33: 125177 | O33: Curso sobre técnicas de negociación y comunicación asertiva | P33: 26-19540 | Q33: 8800 | R33: 46316 | S33: 46323 | T33: =IF(U33="","",IF(U33=W33,1,0)) -> 0 | U33: 1 | V33: 5 | W33: =IF(B33="","",COUNTIFS(Ejecucion[No. Solicitud],Registro!B33,Ejecucion[Estado],"Finalizado")) -> 0 | X33: =IF(B33="","",COUNTIFS(Ejecucion[No. Solicitud],Registro!B33,Ejecucion[Estado],"No Iniciado")) -> 0 | Y33: =IF(B33="","",COUNTIFS(Ejecucion[No. Solicitud],Registro!B33,Ejecucion[Estado],"En Proceso")) -> 1 | Z33: =IF(U33="","",IF(F33="Virtual Asincrónico",1,V33*U33)) -> 1 | AC33: Cooperante | AD33: TRASLADO A DFV - Ruta B
B34: 6315-PFIN-26 | C34: https://sistema-eventos.edu.gt/ticket?id=34 | D34: Resuelto | E34: Media | F34: Virtual Sincrónico | H34: Curso 27 | I34: Mesa de Entrada | J34: 46253.426 | K34: Varias Dependencias | L34: 46253.46 | M34: Gestor 2 | N34: 69221 | O34: Curso de jurisprudencia y sentencia | P34: 26-18315 | Q34: 9000 | R34: 46286 | S34: 46293 | T34: =IF(U34="","",IF(U34=W34,1,0)) -> 1 | U34: 2 | V34: 3 | W34: =IF(B34="","",COUNTIFS(Ejecucion[No. Solicitud],Registro!B34,Ejecucion[Estado],"Finalizado")) -> 2 | X34: =IF(B34="","",COUNTIFS(Ejecucion[No. Solicitud],Registro!B34,Ejecucion[Estado],"No Iniciado")) -> 0 | Y34: =IF(B34="","",COUNTIFS(Ejecucion[No. Solicitud],Registro!B34,Ejecucion[Estado],"En Proceso")) -> 0 | Z34: =IF(U34="","",IF(F34="Virtual Asincrónico",1,V34*U34)) -> 6 | AC34: Externo | AD34: OBLIGATORIO - Primera Vez
B35: 6316-PFIN-26 | C35: https://sistema-eventos.edu.gt/ticket?id=35 | D35: Abierto | E35: Baja | F35: Presencial | H35: Curso 28 | I35: Mesa de Entrada | J35: 46253.438 | K35: Varias Dependencias | L35: 46253.46 | M35: Gestor 2 | N35: 106096 | O35: Curso sobre impugnaciones y medios de impugnación | P35: 26-18318 | Q35: 8000 | R35: 46300 | S35: 46309 | T35: =IF(U35="","",IF(U35=W35,1,0)) -> 0 | U35: 2 | V35: 2 | W35: =IF(B35="","",COUNTIFS(Ejecucion[No. Solicitud],Registro!B35,Ejecucion[Estado],"Finalizado")) -> 0 | X35: =IF(B35="","",COUNTIFS(Ejecucion[No. Solicitud],Registro!B35,Ejecucion[Estado],"No Iniciado")) -> 0 | Y35: =IF(B35="","",COUNTIFS(Ejecucion[No. Solicitud],Registro!B35,Ejecucion[Estado],"En Proceso")) -> 2 | Z35: =IF(U35="","",IF(F35="Virtual Asincrónico",1,V35*U35)) -> 4 | AC35: Externo | AD35: CAMBIO DINÁMICO: Interno a Externo
B36: 6319-PFIN-26 | C36: https://sistema-eventos.edu.gt/ticket?id=36 | D36: Abierto | E36: Baja | F36: Presencial | H36: Curso 29 | I36: Mesa de Entrada | J36: 46254.292 | K36: Varias Dependencias | L36: 46254.422 | M36: Gestor 4 | N36: 124580 | O36: Capacitación de impugnaciones y medios de impugnación con énfasis en la apelación especial y casación | P36: 26-18311 | Q36: 8400 | R36: 46321 | S36: 46324 | T36: =IF(U36="","",IF(U36=W36,1,0)) -> 0 | U36: 2 | V36: 2 | W36: =IF(B36="","",COUNTIFS(Ejecucion[No. Solicitud],Registro!B36,Ejecucion[Estado],"Finalizado")) -> 0 | X36: =IF(B36="","",COUNTIFS(Ejecucion[No. Solicitud],Registro!B36,Ejecucion[Estado],"No Iniciado")) -> 0 | Y36: =IF(B36="","",COUNTIFS(Ejecucion[No. Solicitud],Registro!B36,Ejecucion[Estado],"En Proceso")) -> 2 | Z36: =IF(U36="","",IF(F36="Virtual Asincrónico",1,V36*U36)) -> 4 | AC36: Externo | AD36: CAMBIO DINÁMICO: Interno a Externo
